[2024-04-05T20:17:36.198+0000] {taskinstance.py:1979} INFO - Dependencies all met for dep_context=non-requeueable deps ti=<TaskInstance: dag_postgre_operator.insert_data_task manual__2024-04-05T20:17:29.192951+00:00 [queued]>
[2024-04-05T20:17:36.255+0000] {taskinstance.py:1979} INFO - Dependencies all met for dep_context=requeueable deps ti=<TaskInstance: dag_postgre_operator.insert_data_task manual__2024-04-05T20:17:29.192951+00:00 [queued]>
[2024-04-05T20:17:36.256+0000] {taskinstance.py:2193} INFO - Starting attempt 1 of 1
[2024-04-05T20:17:36.267+0000] {taskinstance.py:2217} INFO - Executing <Task(PostgresBulkLoadOperator): insert_data_task> on 2024-04-05 20:17:29.192951+00:00
[2024-04-05T20:17:36.271+0000] {standard_task_runner.py:60} INFO - Started process 256 to run task
[2024-04-05T20:17:36.274+0000] {standard_task_runner.py:87} INFO - Running: ['***', 'tasks', 'run', 'dag_postgre_operator', 'insert_data_task', 'manual__2024-04-05T20:17:29.192951+00:00', '--job-id', '300', '--raw', '--subdir', 'DAGS_FOLDER/dag_python_operator_extract.py', '--cfg-path', '/tmp/tmpkh2t8j7d']
[2024-04-05T20:17:36.276+0000] {standard_task_runner.py:88} INFO - Job 300: Subtask insert_data_task
[2024-04-05T20:17:36.315+0000] {task_command.py:423} INFO - Running <TaskInstance: dag_postgre_operator.insert_data_task manual__2024-04-05T20:17:29.192951+00:00 [running]> on host 7f6ff1f67725
[2024-04-05T20:17:36.387+0000] {taskinstance.py:2513} INFO - Exporting env vars: AIRFLOW_CTX_DAG_OWNER='***' AIRFLOW_CTX_DAG_ID='dag_postgre_operator' AIRFLOW_CTX_TASK_ID='insert_data_task' AIRFLOW_CTX_EXECUTION_DATE='2024-04-05T20:17:29.192951+00:00' AIRFLOW_CTX_TRY_NUMBER='1' AIRFLOW_CTX_DAG_RUN_ID='manual__2024-04-05T20:17:29.192951+00:00'
[2024-04-05T20:17:36.389+0000] {dag_python_operator_extract.py:88} ERROR - File 'None' not found.
[2024-04-05T20:17:36.390+0000] {taskinstance.py:2731} ERROR - Task failed with exception
Traceback (most recent call last):
  File "/home/airflow/.local/lib/python3.8/site-packages/airflow/models/taskinstance.py", line 444, in _execute_task
    result = _execute_callable(context=context, **execute_callable_kwargs)
  File "/home/airflow/.local/lib/python3.8/site-packages/airflow/models/taskinstance.py", line 414, in _execute_callable
    return execute_callable(context=context, **execute_callable_kwargs)
  File "/opt/airflow/dags/dag_python_operator_extract.py", line 83, in execute
    with open(self.file_path, "r") as f:
FileNotFoundError: [Errno 2] No such file or directory: 'None'
[2024-04-05T20:17:36.399+0000] {taskinstance.py:1149} INFO - Marking task as FAILED. dag_id=dag_postgre_operator, task_id=insert_data_task, execution_date=20240405T201729, start_date=20240405T201736, end_date=20240405T201736
[2024-04-05T20:17:36.408+0000] {standard_task_runner.py:107} ERROR - Failed to execute job 300 for task insert_data_task ([Errno 2] No such file or directory: 'None'; 256)
[2024-04-05T20:17:36.447+0000] {local_task_job_runner.py:234} INFO - Task exited with return code 1
[2024-04-05T20:17:36.460+0000] {logging_mixin.py:188} WARNING - /home/***/.local/lib/python3.8/site-packages/***/models/baseoperator.py:1201 AirflowProviderDeprecationWarning: Call to deprecated class PostgresOperator. (Please use `***.providers.common.sql.operators.sql.SQLExecuteQueryOperator`.Also, you can provide `hook_params={'schema': <database>}`.)
[2024-04-05T20:17:36.470+0000] {taskinstance.py:3312} INFO - 0 downstream tasks scheduled from follow-on schedule check
